Workbook

Sheet Plano mestre 95 % 2025 5% - (4)
R1: PLANEJAMENTO FABRICA | AF1: PLANEJAMENTO FABRICA | AT1: PLANEJAMENTO FABRICA | BH1: PLANEJAMENTO FABRICA | BV1: PLANEJAMENTO FABRICA | CH1: Férias 18/12 - 29/12 | CJ1: PLANEJAMENTO FABRICA | CX1: PLANEJAMENTO FABRICA
D2: 2019 | R2: 2020 | AF2: 2021 | AT2: 2022 | BH2: 2023 | BV2: 2024 | CH2: COMPENSAÇÃO 30 ,31 ,02 e 03 | CJ2: /--------------------------------------------2025 | CX2: 2026
A3: Dias Uteis Produção | C3: =A3 -> Dias Uteis Produção | CH3: 12 dias de férias | CJ3: 23 | CK3: 20 | CL3: 21 | CM3: 22 | CN3: 22 | CO3: 21 | CP3: 23 | CQ3: 21 | CR3: 21 | CS3: 23 | CT3: 20 | CU3: 13 | CX3: 23 | CY3: 20 | CZ3: 21 | DA3: 22 | DB3: 22 | DC3: 21 | DD3: 23 | DE3: 21 | DF3: 21 | DG3: 23 | DH3: 20 | DI3: 13
A4: (-) FÉRIAS | C4: =A4 -> (-) FÉRIAS | CH4: 4 dias de compensação | CJ4: 3 | CL4: 1.5 | CX4: 3 | CY4: 5
A5: (+) SABADO | C5: =A5 -> (+) SABADO | CH5: dias de compensação 9/11 , 23/11 , 7/12 e 14/12 | CJ5: 2 | CK5: 3 | CL5: 1.5 | CM5: 0 | CN5: 0 | CO5: 1.5 | CP5: 1 | CQ5: 1.5 | CR5: 1.5 | CS5: 1.5 | CT5: 0 | DA5: 0 | DB5: 0 | DC5: 0 | DD5: 0 | DE5: 0 | DF5: 0 | DG5: 1 | DH5: 0
A6: (-)FERIADO | C6: =A6 -> (-)FERIADO | CG6: 2 grupos a partir de dezembro | CL6: 2 | CM6: 2 | CN6: 1 | CO6: 1 | CR6: 1 | CS6: 1 | CT6: 1 | CZ6: 2 | DA6: 2 | DB6: 1 | DC6: 1 | DF6: 1 | DG6: 1 | DH6: 1
A7: Dias Trabalhados | C7: =A7 -> Dias Trabalhados | D7: 16 | E7: 21 | F7: 18 | G7: 21 | H7: 22 | I7: 19 | J7: 23 | K7: 21 | L7: 21 | M7: 26 | N7: 24 | O7: 15 | R7: 22 | S7: 20 | T7: 14 | U7: 1 | V7: 12 | W7: 22 | X7: 23 | Y7: 21 | Z7: 21 | AA7: 21 | AB7: 20 | AC7: 17 | AF7: 18 | AG7: 20 | AH7: 20 | AI7: 20 | AJ7: 22 | AK7: 20 | AL7: 22 | AM7: 22 | AN7: 21 | AO7: 20 | AP7: 20 | AQ7: 12 | AT7: 19 | AU7: 19 | AV7: 18 | AW7: 19 | AX7: 22 | AY7: 21 | AZ7: 21 | BA7: 22 | BB7: 22 | BC7: 21 | BD7: 20 | BE7: 10 | BH7: 20 | BI7: 17 | BJ7: 23 | BK7: 18 | BL7: 22 | BM7: 23 | BN7: 21 | BO7: 21 | BP7: 20 | BQ7: 21 | BR7: 20 | BS7: 14 | BT7: 20 | BV7: 19 | BW7: 19 | BX7: 21 | BY7: =22+2 -> 24 | BZ7: =21+2 -> 23 | CA7: =20+2 -> 22 | CB7: =23+2 -> 25 | CC7: =21+3 -> 24 | CD7: =21+3 -> 24 | CE7: =23+1 -> 24 | CF7: =19+3 -> 22 | CG7: =12+1 -> 13 | CJ7: =CJ3+CJ5-CJ6-CJ4 -> 22 | CK7: =CK3+CK5-CK6-CK4 -> 23 | CL7: 19 | CM7: =CM3+CM5-CM6-CM4 -> 20 | CN7: =CN3+CN5-CN6-CN4 -> 21 | CO7: =CO3+CO5-CO6-CO4 -> 21.5 | CP7: =CP3+CP5-CP6 -> 24 | CQ7: =CQ3+CQ5-CQ6 -> 22.5 | CR7: =CR3+CR5-CR6 -> 21.5 | CS7: =CS3+CS5-CS6 -> 23.5 | CT7: =CT3+CT5-CT6 -> 19 | CU7: =CU3+CU5-CU6 -> 13 | CX7: =CX3+CX5-CX6-CX4 -> 20 | CY7: =CY3+CY5-CY6-CY4 -> 15 | CZ7: =CZ3+CZ5-CZ6-CZ4 -> 19 | DA7: =DA3+DA5-DA6-DA4 -> 20 | DB7: =DB3+DB5-DB6-DB4 -> 21 | DC7: =DC3+DC5-DC6-DC4 -> 20 | DD7: =DD3+DD5-DD6 -> 23 | DE7: =DE3+DE5-DE6 -> 21 | DF7: =DF3+DF5-DF6 -> 20 | DG7: =DG3+DG5-DG6 -> 23 | DH7: =DH3+DH5-DH6 -> 19 | DI7: =DI3+DI5-DI6 -> 13
D8: JAN | E8: FEV | F8: MAR | G8: ABR | H8: MAI | I8: JUN | J8: JUL | K8: AGO | L8: SET | M8: OUT | N8: NOV | O8: DEZ | P8: TOTAL | R8: JAN | S8: FEV | T8: MAR | U8: ABR | V8: MAI | W8: JUN | X8: JUL | Y8: AGO | Z8: SET | AA8: OUT | AB8: NOV | AC8: DEZ | AD8: TOTAL | AF8: JAN | AG8: FEV | AH8: MAR | AI8: ABR | AJ8: MAI | AK8: JUN | AL8: JUL | AM8: AGO | AN8: SET | AO8: OUT | AP8: NOV | AQ8: DEZ | AR8: TOTAL | AT8: JAN | AU8: FEV | AV8: MAR | AW8: ABR | AX8: MAI | AY8: JUN | AZ8: JUL | BA8: AGO | BB8: SET | BC8: OUT | BD8: NOV | BE8: DEZ | BF8: TOTAL | BH8: JAN | BI8: FEV | BJ8: MAR | BK8: ABR | BL8: MAI | BM8: JUN | BN8: JUL | BO8: AGO | BP8: SET | BQ8: OUT | BR8: NOV | BS8: DEZ | BT8: TOTAL | BV8: JAN | BW8: FEV | BX8: MAR | BY8: ABR | BZ8: MAI | CA8: JUN | CB8: JUL | CC8: AGO | CD8: SET | CE8: OUT | CF8: NOV | CG8: DEZ | CH8: TOTAL | CJ8: JAN | CK8: FEV | CL8: MAR | CM8: ABR | CN8: MAI | CO8: JUN | CP8: JUL | CQ8: AGO | CR8: SET | CS8: OUT | CT8: NOV | CU8: DEZ | CV8: TOTAL | CX8: JAN | CY8: FEV | CZ8: MAR | DA8: ABR | DB8: MAI | DC8: JUN | DD8: JUL | DE8: AGO | DF8: SET | DG8: OUT | DH8: NOV | DI8: DEZ | DJ8: TOTAL
CI9: redução de meta | CW9: redução de meta
A10: ESTOQUE FÍSICO | B10: Total (1+2) DISPONÍVEL TOTAL | D10: =SUM(D15:D17) -> 304786 | E10: =SUM(E15:E17) -> 311986 | F10: =SUM(F15:F17) -> 328231 | G10: =SUM(G15:G17) -> 317873 | H10: =SUM(H15:H17) -> 347196 | I10: =SUM(I15:I17) -> 402253 | J10: =SUM(J15:J17) -> 454488 | K10: =SUM(K15:K17) -> 447182 | ... O10: =SUM(O15:O17) -> 188264 | R10: =SUM(R15:R17) -> 283359 | S10: =SUM(S15:S17) -> 342718 | T10: =SUM(T15:T17) -> 313212 | U10: =SUM(U15:U17) -> 298093 | V10: =SUM(V15:V17) -> 206617 | W10: =SUM(W15:W17) -> 235875 | X10: =SUM(X15:X17) -> 360135 | Y10: =SUM(Y15:Y17) -> 361665 | ... AC10: =SUM(AC15:AC17) -> 197551 | AF10: =SUM(AF15:AF19) -> 255339 | AG10: =SUM(AG15:AG19) -> 292621 | AH10: =SUM(AH15:AH19) -> 397976 | AI10: =SUM(AI15:AI19) -> 388165 | AJ10: =SUM(AJ15:AJ19) -> 409301 | AK10: =SUM(AK15:AK19) -> 490913 | AL10: =SUM(AL15:AL19) -> 563229 | AM10: =SUM(AM15:AM19) -> 559169 | ... AQ10: =SUM(AQ15:AQ19) -> 531679 | AR10: =AQ10 -> 531679 | AT10: =SUM(AT15:AT19) -> 471378 | AU10: =SUM(AU15:AU19) -> 473307 | AV10: =SUM(AV15:AV19) -> 412518 | AW10: =SUM(AW15:AW19) -> 398039 | AX10: =SUM(AX15:AX19) -> 417827 | AY10: =SUM(AY15:AY19) -> 507968 | AZ10: =SUM(AZ15:AZ19) -> 477530 | BA10: =SUM(BA15:BA19) -> 520708 | ... BE10: =SUM(BE15:BE19) -> 356505 | BF10: =BE10 -> 356505 | BH10: =SUM(BH15:BH19) -> 357143 | BI10: =SUM(BI15:BI19) -> 355011 | BJ10: =SUM(BJ15:BJ19) -> 344281 | BK10: =SUM(BK15:BK19) -> 389628 | BL10: =SUM(BL15:BL19) -> 324889 | BM10: =SUM(BM15:BM19) -> 352666 | BN10: =SUM(BN15:BN19) -> 418721 | BO10: =SUM(BO15:BO19) -> 356602 | ... BR10: =SUM(BR15:BR19) -> 228035 | BS10: =BS15+BS16+BS19 -> 201165 | BT10: =BS10 -> 201165 | BV10: =BV11+BV16+BV19 -> 247713 | BW10: =BW11+BW16+BW19 -> 278707 | BX10: =BX11+BX16+BX19 -> 281829 | BY10: =BY11+BY16+BY19 -> 317753 | BZ10: =BZ11+BZ16+BZ19 -> 270339 | CA10: =CA11+CA16+CA19 -> 310383 | CB10: =CB11+CB16+CB19 -> 328365 | CC10: =CC11+CC16+CC19 -> 333476 | ... CG10: =CG11+CG16+CG19 -> 182266 | CH10: =CH15+CH16+CH19 -> 161447 | CJ10: =CH10+CJ71-CJ27 -> 145024.06 | CK10: =CJ10+CK71-CK27 -> 167771.39 | CL10: =CK10+CL71-CL27 -> 152974.71 | CM10: =CL10+CM71-CM27 -> 172918.05 | CN10: =CM10+CN71-CN27 -> 208116.1 | CO10: =CN10+CO71-CO27 -> 281435.22 | CP10: =CO10+CP71-CP27 -> 271715.13 | CQ10: =CP10+CQ71-CQ27 -> 271819.82 | CR10: =CQ10+CR71-CR27 -> 212966.18 | ... CU10: =CT10+CU71-CU27 -> 228180.35 | CV10: 116080.11 | CX10: =CV10+CX71-CX27 -> 109586.02 | CY10: =CX10+CY71-CY27 -> 73440.716 | CZ10: =CY10+CZ71-CZ27 -> 53154.202 | DA10: =CZ10+DA71-DA27 -> 69094.709 | DB10: =DA10+DB71-DB27 -> 100802.66 | DC10: =DB10+DC71-DC27 -> 158612.74 | DD10: =DC10+DD71-DD27 -> 133206.64 | DE10: =DD10+DE71-DE27 -> 109166.57 | DF10: =DE10+DF71-DF27 -> 23680.246 | ... DI10: =DH10+DI71-DI27 -> 9525.1244 | DJ10: 116080.11
A11: 0 | B11: ESTOQUE FISICO EM LINHA | BV11: 204006 | BW11: 241182 | BX11: 245950 | BY11: 281974 | BZ11: 202865 | CA11: 240895 | CB11: 273565 | CC11: 288981 | CD11: 273990 | CE11: 237556 | CF11: 168313 | CG11: 150819 | CH11: =CG11 -> 150819 | CJ11: 205037 | CK11: 230430 | CL11: 234343 | CM11: 262404
A12: 0 | B12: PEDIDOS EM CARTEIRA | BV12: 80956 | BW12: 110544 | BX12: 134506 | BY12: 127959 | BZ12: 66136 | CA12: 72582 | CB12: 94286 | CC12: 133081 | CD12: 148174 | CE12: 154201 | CF12: 97365 | CG12: 30184 | CJ12: 132209 | CK12: 180000 | CL12: 177643 | CM12: 148159
A13: 0 | B13: PROCESSO | CJ13: 150321 | CK13: 133602 | CL13: 135672 | CM13: 127653
A14: 0 | B14: ESTOQUE NEGATIVO | CJ14: 36757 | CK14: 55826 | CL14: 60438 | CM14: 50114
A15: 1 | B15: EM LINHA DISPONIVEL | D15: 197000 | E15: 223027 | F15: 230513 | G15: 231174 | H15: 255028 | I15: =316386+3241 -> 319627 | J15: 377712 | K15: 382411 | L15: 394107 | M15: 267954 | O15: 143875 | R15: 208084 | S15: 268431 | T15: 250616 | U15: 237088 | V15: 147777 | W15: 215818 | X15: 273510 | Y15: 299059 | Z15: 304980 | AA15: 231197 | AB15: 143086 | AC15: 172491 | AF15: 198695 | AG15: 234210 | AH15: 327560 | AI15: 332523 | AJ15: 356667 | AK15: 384165 | AL15: 317268 | AM15: 370708 | AN15: 354503 | AO15: 314605 | AP15: 90490 | AQ15: 58348 | AR15: =AQ15 -> 58348 | AT15: 158701 | AU15: 115369 | AV15: 142379 | AW15: 118765 | AX15: 113246 | AY15: 106776 | AZ15: 175234 | BA15: 151553 | BB15: 167082 | BC15: 150959 | BD15: 119787 | BE15: 65426 | BF15: =BE15 -> 65426 | BH15: 166918 | BI15: 167160 | BJ15: 204571 | BK15: 153197 | BL15: 196798 | BM15: 145596 | BN15: 166021 | BO15: 211305 | BP15: 201071 | BQ15: 177743 | BR15: 144020 | BS15: 154347 | BT15: =BS15 -> 154347 | BV15: 151471 | BW15: 155653 | BX15: 151611 | BY15: 177044 | BZ15: 170481 | CA15: 221665 | CB15: 218105 | CC15: 188153 | CD15: 147751 | CE15: 112996 | CF15: 135968 | CG15: 130000 | CH15: =CG15 -> 130000 | CI15: 114000 | CJ15: 109585 | CK15: 103815 | CL15: 117138 | CM15: =CL15+CM71-CM27 -> 137081.34 | CN15: =CM15+CN71-CN27 -> 172279.39 | CO15: =CN15+CO71-CO27 -> 245598.51 | CP15: =CO15+CP71-CP27 -> 235878.42 | CQ15: =CP15+CQ71-CQ27 -> 235983.11 | CR15: =CQ15+CR71-CR27 -> 177129.47 | CS15: =CR15+CS71-CS27 -> 163912.55 | CT15: =CS15+CT71-CT27 -> 175927.46 | CU15: =CT15+CU71-CU27 -> 192343.64 | CX15: =CU15+CX71-CX27 -> 185849.55 | CY15: =CX15+CY71-CY27 -> 149704.25 | CZ15: =CY15+CZ71-CZ27 -> 129417.74 | DA15: =CZ15+DA71-DA27 -> 145358.24 | DB15: =DA15+DB71-DB27 -> 177066.2 | DC15: =DB15+DC71-DC27 -> 234876.27 | DD15: =DC15+DD71-DD27 -> 209470.18 | DE15: =DD15+DE71-DE27 -> 185430.1 | DF15: =DE15+DF71-DF27 -> 99943.779 | ... DI15: =DH15+DI71-DI27 -> 85788.657 | DJ15: 0
A16: 2 | B16: EM LINHA NAO COMPRAR MP DISPONIVEL | D16: 73670 | E16: 59682 | F16: 54710 | G16: 56175 | H16: 58933 | I16: 42784 | J16: 35755 | K16: 33547 | L16: 22824 | M16: 26162 | O16: 44389 | R16: 39759 | S16: 38325 | T16: 26634 | U16: =14430+2754+7859 -> 25043 | V16: 23840 | W16: 20057 | X16: 80502 | Y16: 56483 | Z16: 44233 | AA16: 38155 | AB16: 27540 | AC16: 25060 | AF16: 21326 | AG16: 17804 | AH16: 27157 | AI16: 19677 | AJ16: 18817 | AK16: 25034 | AL16: 28090 | AM16: 25660 | AN16: 33752 | AO16: 24699 | AP16: 19340 | AQ16: 29842 | AR16: =AQ16 -> 29842 | AT16: 46493 | AU16: 37125 | AV16: 38574 | AW16: 43626 | AX16: 39641 | AY16: 55553 | AZ16: 48023 | BA16: 55043 | BB16: 50383 | BC16: 54355 | BD16: 82473 | BE16: 65398 | BF16: =BE16 -> 65398 | BH16: 68747 | BI16: 62843 | BJ16: 62154 | BK16: 49337 | BL16: 27730 | BM16: 42459 | BN16: 44049 | BO16: 29196 | BP16: 36882 | BQ16: 35965 | BR16: 31343 | BS16: 23087 | BT16: =BS16 -> 23087 | BV16: 15202 | BW16: 12471 | BX16: 11483 | BY16: 14071 | BZ16: 49617 | CA16: 36385 | CB16: 25473 | CC16: 16933 | CD16: 12684 | CE16: 21084 | CF16: 15172 | CG16: 11469 | CH16: =CG16 -> 11469 | CI16: =7500*5 -> 37500 | CJ16: 9465 | CK16: 13722 | CL16: 10771 | CM16: 8991 | CV16: 0 | DJ16: 0
A17: 3 | B17: EM LINHA PARADO (cob >3) DISPONIVEL | D17: 34116 | E17: 29277 | F17: 43008 | G17: 30524 | H17: 33235 | I17: 39842 | J17: 41021 | K17: 31224 | M17: 10286 | R17: 35516 | S17: 35962 | T17: 35962 | U17: 35962 | V17: 35000 | X17: 6123 | Y17: 6123 | Z17: 4187 | AA17: 2745 | AF17: 8366 | AG17: 11534 | AH17: 11507 | AI17: 9148 | AJ17: 8524 | AK17: 25290 | AL17: 91080 | AM17: 66830 | AN17: 36866 | AO17: 16173 | AP17: 178274 | AQ17: 210665 | AR17: =AQ17 -> 210665 | AT17: 121075 | AU17: 149376 | AV17: 104538 | AW17: 105262 | AX17: 121073 | AY17: 163931 | AZ17: 109964 | BA17: 148266 | BB17: 130697 | BC17: 113779 | BD17: 91119 | BE17: 103286 | BF17: =BE17 -> 103286 | BH17: 49631 | BI17: 52953 | BJ17: 28440 | BK17: 83601 | BL17: 25812 | BM17: 59545 | BN17: 83435 | BO17: 34041 | BP17: 22399 | BQ17: 24887 | BR17: 12183 | BS17: 12183 | BT17: =BS17 -> 12183 | BV17: 5216 | BX17: 65273 | BY17: 70182 | BZ17: 57659 | CA17: 71669 | CB17: 73078 | CC17: 85302 | CD17: 25343 | CE17: 19030 | CF17: 19422 | CG17: 25927 | CH17: =CG17 -> 25927 | CI17: 29000 | CJ17: 21580 | CK17: 18052 | CL17: 30722 | CM17: 55095 | CV17: 0 | DJ17: 0
A18: 4 | B18: EM LINHA PARADO (cob >6) DISPONIVEL | D18: 34116 | E18: 29277 | F18: 43008 | G18: 30524 | H18: 33235 | I18: 39842 | J18: 41021 | K18: 31224 | M18: 10286 | R18: 35516 | S18: 35962 | T18: 35962 | U18: 35962 | V18: 35000 | X18: 6123 | Y18: 6123 | Z18: 4187 | AA18: 2745 | AF18: 8366 | AG18: 11534 | AH18: 11507 | AI18: 9148 | AJ18: 8524 | AK18: 25290 | AL18: 91080 | AM18: 66830 | AN18: 36866 | AO18: 16173 | AP18: 178274 | AQ18: 210665 | AR18: =AQ18 -> 210665 | AT18: 121075 | AU18: 149376 | AV18: 104538 | AW18: 105262 | AX18: 121073 | AY18: 163931 | AZ18: 109964 | BA18: 148266 | BB18: 130697 | BC18: 113779 | BD18: 91119 | BE18: 103286 | BF18: =BE18 -> 103286 | BH18: 49631 | BI18: 52953 | BJ18: 28440 | BK18: 83601 | BL18: 25812 | BM18: 59545 | BN18: 83435 | BO18: 34041 | BP18: 22399 | BQ18: 24887 | BR18: 12183 | BS18: 12183 | BT18: =BS18 -> 12183 | CD18: 6361 | CE18: 7759 | CF18: 6573 | CG18: 9541 | CH18: =CG18 -> 9541 | CI18: =CI15+CI16-CI17 -> 122500 | CJ18: 9582 | CK18: 7266 | CL18: 11364 | CM18: 15500 | CV18: 0 | DJ18: 0
A19: 1 | B19: FL (OPORTUNIDADES) DISPONIVEL | D19: 6409 | E19: 6860 | F19: 4970 | G19: 31203 | H19: 31499 | I19: 25903 | J19: 18606 | K19: 16014 | L19: 13416 | M19: 40079 | O19: 0 | R19: 3376 | S19: 11736 | T19: 22454 | U19: 21384 | V19: 66870 | W19: 73769 | X19: 13944 | Y19: 32750 | Z19: 18536 | AA19: 40211 | AB19: 44457 | AC19: 24504 | AF19: 18586 | AG19: 17539 | AH19: 20245 | AI19: 17669 | AJ19: 16769 | AK19: 31134 | AL19: 35711 | AM19: 29141 | AN19: 25307 | AO19: 35964 | AP19: 37378 | AQ19: 22159 | AR19: =AQ19 -> 22159 | AT19: 24034 | AU19: 22061 | AV19: 22489 | AW19: 25124 | AX19: 22794 | AY19: 17777 | AZ19: 34345 | BA19: 17580 | BB19: 26992 | BC19: 21373 | BD19: 21202 | BE19: 19109 | BF19: =BE19 -> 19109 | BH19: 22216 | BI19: 19102 | BJ19: 20676 | BK19: 19892 | BL19: 48737 | BM19: 45521 | BN19: 41781 | BO19: 48019 | BP19: 43955 | BQ19: 41505 | BR19: 28306 | BS19: 23731 | BT19: =BS19 -> 23731 | BV19: 28505 | BW19: 25054 | BX19: 24396 | BY19: 21708 | BZ19: 17857 | CA19: 33103 | CB19: 29327 | CC19: 27562 | CD19: 19590 | CE19: 11730 | CF19: 10529 | CG19: 19978 | CH19: =CG19 -> 19978 | CJ19: 18456 | CK19: 15409 | CL19: 18755 | CM19: 15700 | CV19: 0 | DJ19: 0
A20: 0 | B20: EM LINHA NAO COMPRAR MP FISICO | CE20: 34501 | CF20: 18809 | CG20: 12618 | CJ20: 11940 | CK20: 19956 | CL20: 15650 | CM20: 11745
A21: 0 | B21: FL(OPORTUNIDADE) FISICO | CE21: 12837 | CF21: 11839 | CG21: 20519 | CJ21: 17816 | CK21: 17432 | CL21: 21670 | CM21: 19814
B22: SALDO UTIL DE ESTOQUE | D22: =D10-D17 -> 270670 | E22: =E10-E17 -> 282709 | F22: =F10-F17 -> 285223 | G22: =G10-G17 -> 287349 | H22: =H10-H17 -> 313961 | I22: =I10-I17 -> 362411 | J22: =J10-J17 -> 413467 | K22: =K10-K17 -> 415958 | ... O22: =O10-O17 -> 188264 | R22: =R10-R17 -> 247843 | S22: =S10-S17 -> 306756 | T22: =T10-T17 -> 277250 | U22: =U10-U17 -> 262131 | V22: =V10-V17 -> 171617 | W22: =W10-W17 -> 235875 | X22: =X10-X17 -> 354012 | Y22: =Y10-Y17 -> 355542 | ... AB22: =AB10-AB17 -> 170626 | AF22: =AF10-AF17 -> 246973 | AG22: =AG10-AG17 -> 281087 | AH22: =AH10-AH17 -> 386469 | AI22: =AI10-AI17 -> 379017 | AJ22: =AJ10-AJ17 -> 400777 | AK22: =AK10-AK17 -> 465623 | AL22: =AL10-AL17 -> 472149 | AM22: =AM10-AM17 -> 492339 | ... AQ22: =AQ10-AQ17 -> 321014 | AR22: =AQ22 -> 321014 | AT22: =AT10-AT17 -> 350303 | AU22: =AU10-AU17 -> 323931 | AV22: =AV10-AV17 -> 307980 | AW22: =AW10-AW17 -> 292777 | AX22: =AX10-AX17 -> 296754 | AY22: =AY10-AY17 -> 344037 | AZ22: =AZ10-AZ17 -> 367566 | BA22: =BA10-BA17 -> 372442 | ... BE22: =BE10-BE17 -> 253219 | BF22: =BE22 -> 253219 | BH22: =BH10-BH17 -> 307512 | BI22: =BI10-BI17 -> 302058 | BJ22: =BJ10-BJ17 -> 315841 | BK22: =BK10-BK17 -> 306027 | BL22: =BL10-BL17 -> 299077 | BM22: =BM10-BM17 -> 293121 | BN22: =BN10-BN17 -> 335286 | BO22: =BO10-BO17 -> 322561 | ... BS22: =BS10-BS17 -> 188982 | BT22: =BS22 -> 188982 | BV22: =BV15-BV17-BV18 -> 146255 | BW22: =BW15-BW17-BW18 -> 155653 | BX22: =BX15-BX17-BX18 -> 86338 | BY22: =BY15-BY17-BY18 -> 106862 | BZ22: =BZ15-BZ17-BZ18 -> 112822 | CA22: =CA15-CA17-CA18 -> 149996 | CB22: =CB15-CB17-CB18 -> 145027 | CC22: =CC15-CC17-CC18 -> 102851 | ... CH22: =CH15-CH17-CH18 -> 94532 | CJ22: =CJ15-CJ17-CJ18 -> 78423 | CK22: =CK15-CK17-CK18 -> 78497 | CL22: =CL15-CL17-CL18 -> 75052 | CM22: =CM15-CM17-CM18 -> 66486.34 | CN22: =CN15-CN17-CN18 -> 172279.39 | CO22: =CO15-CO17-CO18 -> 245598.51 | CP22: =CP15-CP17-CP18 -> 235878.42 | CQ22: =CQ15-CQ17-CQ18 -> 235983.11 | ... CU22: =CU15-CU17-CU18 -> 192343.64 | CV22: 116080.11 | CX22: 242497 | CY22: 234422.08 | CZ22: 194348.71 | DA22: 223062.99 | DB22: 228884.87 | DC22: 240669.79 | DD22: 234679.66 | DE22: 197008.01 | DF22: 148007.96 | DG22: 111276.3 | DH22: 93072.106 | DI22: 116080.11 | DJ22: 116080.11
A23: ESTOQUE EM LINHA | C23: (1-3-5) | D23: =D15-D17 -> 162884 | E23: =E15+E19-E17-E60 -> 200610 | F23: =F15+F19-F17-F60 -> 192475 | G23: =G15+G19-G17-G60 -> 231853 | H23: =H15+H19-H17-H60 -> 253292 | I23: =I15+I19-I17-I60 -> 305688 | J23: =J15+J19-J17-J60 -> 355297 | K23: =K15+K19-K17-K60 -> 367201 | L23: =L15+L19-L17-L60 -> 407523 | ... O23: =O15+O19-O17-O60 -> 143875 | P23: =J23 -> 355297 | R23: =R15-R17 -> 172568 | S23: =S15+S19-S17-S60 -> 244205 | T23: =T15+T19-T17-T60 -> 237108 | U23: =U15+U19-U17-U60 -> 222510 | V23: =V15+V19-V17-V60 -> 179647 | W23: =W15+W19-W17-W60 -> 289587 | X23: =X15+X19-X17-X60 -> 281331 | Y23: =Y15+Y19-Y17-Y60 -> 325686 | Z23: =Z15+Z19-Z17-Z60 -> 319329 | ... AC23: =AC15+AC19-AC17-AC60 -> 196995 | AD23: =X23 -> 281331 | AF23: =AF15+AF17+AF16 -> 228387 | AG23: =AG15+AG17+AG16 -> 263548 | AH23: =AH15+AH17+AH16 -> 366224 | AI23: =AI15+AI17+AI16 -> 361348 | AJ23: =AJ15+AJ17+AJ16 -> 384008 | AK23: =AK15+AK17+AK16 -> 434489 | AL23: =AL15+AL17+AL16 -> 436438 | AM23: =AM15+AM17+AM16 -> 463198 | ... AQ23: =AQ15+AQ17+AQ16 -> 298855 | AR23: =AQ23 -> 298855 | AT23: =AT15+AT17+AT16 -> 326269 | AU23: =AU15+AU17+AU16 -> 301870 | AV23: =AV15+AV17+AV16 -> 285491 | AW23: =AW15+AW17+AW16 -> 267653 | AX23: =AX15+AX17+AX16 -> 273960 | AY23: =AY15+AY17+AY16 -> 326260 | AZ23: =AZ15+AZ17+AZ16 -> 333221 | BA23: =BA15+BA17+BA16 -> 354862 | ... BE23: =BE15+BE17+BE16 -> 234110 | BF23: =SUM(AT23:BE23) -> 3664330 | BH23: =BH15+BH17+BH16 -> 285296 | BI23: =BI15+BI17+BI16 -> 282956 | BJ23: =BJ15+BJ17+BJ16 -> 295165 | BK23: =BK15+BK17+BK16 -> 286135 | BL23: =BL15+BL17+BL16 -> 250340 | BM23: =BM15+BM17+BM16 -> 247600 | BN23: =BN15+BN17+BN16 -> 293505 | BO23: =BO15+BO17+BO16 -> 274542 | ... BS23: =BS15+BS17+BS16 -> 189617 | BT23: =BS23 -> 189617 | BV23: =BV15+BV17+BV16 -> 171889 | BW23: =BW15+BW19+BW16 -> 193178 | BX23: =BX15+BX17+BX16 -> 228367 | BY23: =BY15+BY17+BY16 -> 261297 | BZ23: =BZ15+BZ17+BZ16 -> 277757 | CA23: =CA15+CA17+CA16 -> 329719 | CB23: =CB15+CB17+CB16 -> 316656 | CC23: =CC15+CC17+CC16 -> 290388 | CD23: =CD15+CD17+CD16 -> 185778 | CE23: =CE15+CE17+CE16 -> 153110 | ... CG23: =CG15+CG17+CG16 -> 167396 | CH23: =CG23 -> 167396 | CJ23: 224424 | CK23: 0 | CL23: 0 | CM23: 0 | CN23: 0 | CO23: 0 | CP23: 0 | CQ23: 0 | CR23: 0 | CS23: 0 | CT23: 0 | CU23: 0 | CV23: 0 | CX23: 224424 | CY23: 0 | CZ23: 0 | DA23: 0 | DB23: 0 | DC23: 0 | DD23: 0 | DE23: 0 | DF23: 0 | DG23: 0 | DH23: 0 | DI23: 0 | DJ23: 0
A24: ESTOQUE EM LINHA SEM SALDO PARADO | C24: (1-3-5-6+7) | D24: =D10-D19-D17 -> 264261 | E24: =E10-E19-E17 -> 275849 | F24: =F10-F19-F17 -> 280253 | G24: =G10-G19-G17 -> 256146 | H24: =H10-H19-H17 -> 282462 | I24: =I10-I19-I17 -> 336508 | J24: =J10-J19-J17 -> 394861 | K24: =K10-K19-K17 -> 399944 | ... O24: =O10-O19-O17 -> 188264 | P24: =O24 -> 188264 | R24: =R10-R19-R17 -> 244467 | S24: =S10-S19-S17 -> 295020 | T24: =T10-T19-T17 -> 254796 | U24: =U10-U19-U17 -> 240747 | V24: =V10-V19-V17 -> 104747 | W24: =W10-W19-W17 -> 162106 | X24: =X10-X19-X17 -> 340068 | Y24: =Y10-Y19-Y17 -> 322792 | ... AC24: =AC10-AC19-AC17 -> 173047 | AD24: =AC24 -> 173047 | AF24: =AF23-AF17 -> 220021 | AG24: =AG23-AG17 -> 252014 | AH24: =AH23-AH17 -> 354717 | AI24: =AI23-AI17 -> 352200 | AJ24: =AJ23-AJ17 -> 375484 | AK24: =AK23-AK17 -> 409199 | AL24: =AL23-AL17 -> 345358 | AM24: =AM23-AM17 -> 396368 | ... AQ24: =AQ23-AQ17 -> 88190 | AR24: =AQ24 -> 88190 | AT24: =AT23-AT17 -> 205194 | AU24: =AU23-AU17 -> 152494 | AV24: =AV23-AV17 -> 180953 | AW24: =AW23-AW17 -> 162391 | AX24: =AX23-AX17 -> 152887 | AY24: =AY23-AY17 -> 162329 | AZ24: =AZ23-AZ17 -> 223257 | BA24: =BA23-BA17 -> 206596 | ... BE24: =BE23-BE17 -> 130824 | BF24: =SUM(AT24:BE24) -> 2201964 | BG24: =SUM(AT27:AY27)/SUM(AF61:AK61)-1 -> 0.22832581 | BH24: =BH23-BH17 -> 235665 | BI24: =BI23-BI17 -> 230003 | BJ24: =BJ23-BJ17 -> 266725 | BK24: =BK23-BK17 -> 202534 | BL24: =BL23-BL17 -> 224528 | BM24: =BM23-BM17 -> 188055 | BN24: =BN23-BN17 -> 210070 | BO24: =BO23-BO17 -> 240501 | ... BS24: =BS23-BS17 -> 177434 | BT24: =BS24 -> 177434 | BV24: =BV23-BV17 -> 166673 | BW24: =BW23-BW17 -> 193178 | BX24: =BX23-BX17 -> 163094 | BY24: =BY23-BY17 -> 191115 | BZ24: =BZ23-BZ17 -> 220098 | CA24: =CA23-CA17 -> 258050 | CB24: =CB23-CB17 -> 243578 | CC24: =CC23-CC17 -> 205086 | ... CG24: =CG23-CG17 -> 141469 | CH24: =CG24 -> 141469 | CJ24: 219208 | CK24: 0 | CL24: 0 | CM24: 0 | CN24: 0 | CO24: 0 | CP24: 0 | CQ24: 0 | CR24: 0 | CS24: 0 | CT24: 0 | CU24: 0 | CV24: 0 | CX24: 219208 | CY24: 0 | CZ24: 0 | DA24: 0 | DB24: 0 | DC24: 0 | DD24: 0 | DE24: 0 | DF24: 0 | DG24: 0 | DH24: 0 | DI24: 0 | DJ24: 0
A25: PROJEÇÃO DOS ESTOQUES DISPONIVEL | C25: (1-5-6+7) | D25: =D10 -> 304786 | E25: =E10 -> 311986 | F25: =F10 -> 328231 | G25: =G10 -> 317873 | H25: =H10 -> 347196 | I25: =I10 -> 402253 | J25: =J10 -> 454488 | K25: =K10 -> 447182 | ... O25: =O10 -> 188264 | P25: =O25 -> 188264 | R25: =R10 -> 283359 | S25: =S10 -> 342718 | T25: =T10 -> 313212 | U25: =U10 -> 298093 | V25: =V10 -> 206617 | W25: =W10 -> 235875 | X25: =X10 -> 360135 | Y25: =Y10 -> 361665 | ... AC25: =AC10 -> 197551 | AD25: =AC25 -> 197551 | AF25: =AF10-AF60 -> 255339 | AG25: =AG10-AG60 -> 292621 | AH25: =AH10-AH60 -> 397976 | AI25: =AI10-AI60 -> 388165 | AJ25: =AJ10-AJ60 -> 409301 | AK25: =AK10-AK60 -> 490913 | AL25: =AL10-AL60 -> 563229 | AM25: =AM10-AM60 -> 559169 | ... AQ25: =AQ10-AQ60 -> 522741 | AR25: =AQ25 -> 522741 | AT25: =AT10-AT60 -> 364736 | AU25: =AU10-AU60 -> 382608 | AV25: =AV10-AV60 -> 322837 | AW25: =AW10-AW60 -> 339249 | AX25: =AX10-AX60 -> 382307 | AY25: =AY10-AY60 -> 446417 | AZ25: =AZ10-AZ60 -> 406019 | BA25: =BA10-BA60 -> 457091 | BB25: =BB10-BB60 -> 439103 | BC25: =BB25-BC27+BC71-BC60 -> 267702.71 | BD25: =BC25-BD27+BD71-BD60 -> 224792.12 | BE25: =BD25-BE27+BE71-BE60 -> 209302.51 | BF25: =BE25 -> 209302.51 | BG25: =BG27/AR27 -> 0.070333736 | BH25: =BH10-BH60 -> 287739 | BI25: =BI10-BI60 -> 274599 | BJ25: =BJ10-BJ60 -> 249895 | BK25: =BK10-BK60 -> 311315 | BL25: =BL10-BL60 -> 277855 | BM25: =BM10-BM60 -> 301815 | BN25: =BN10-BN60 -> 325519 | BO25: =BO10-BO60 -> 255915 | ... BS25: =BS10-BS60 -> 201165 | BT25: =BS25 -> 201165 | BV25: =BV10-BV60 -> 247713 | BW25: =BW10-BW60 -> 278707 | BX25: =BX10-BX60 -> 281829 | BY25: =BY10-BY60 -> 317753 | BZ25: =BZ10-BZ60 -> 270339 | CA25: =CA10-CA60 -> 310383 | CB25: =CB10-CB60 -> 328365 | CC25: =CC10-CC60 -> 333476 | ... CG25: =CG10-CG60 -> 182266 | CH25: =CG25 -> 182266 | CJ25: 247713 | CK25: 234422.08 | CL25: 194348.71 | CM25: 223062.99 | CN25: 228884.87 | CO25: 240669.79 | CP25: 234679.66 | CQ25: 197008.01 | CR25: 148007.96 | CS25: 111276.3 | CT25: 93072.106 | CU25: 116080.11 | CV25: 116080.11 | CW25: =CV27-459000 -> 1692766.6 | CX25: 247713 | CY25: 234422.08 | CZ25: 194348.71 | DA25: 223062.99 | DB25: 228884.87 | DC25: 240669.79 | DD25: 234679.66 | DE25: 197008.01 | DF25: 148007.96 | DG25: 111276.3 | DH25: 93072.106 | DI25: 116080.11 | DJ25: 116080.11
B26: Cobertura de Estoque | AF26: =AF10/AG27 -> 1.4346741 | AG26: =AG10/AH27 -> 3.9745328 | AH26: =AH10/AI27 -> 4.4537255 | AI26: =AI10/AJ27 -> 3.1781895 | AJ26: =AJ10/AK27 -> 2.7551225 | AK26: =AK10/AL27 -> 3.229797 | AL26: =AL10/AM27 -> 2.3575635 | AM26: =AM10/AN27 -> 2.1413161 | ... AP26: =AP10/AQ27 -> 5.1487735 | AQ26: =AQ10/AT27 -> 3.4807307 | AR26: =AQ26 -> 3.4807307 | AT26: =AT10/AU27 -> 2.7971286 | AU26: =AU10/AV27 -> 3.0710064 | AV26: =AV10/AW27 -> 2.584778 | AW26: =AW10/AX27 -> 3.3142308 | AX26: =AX10/AY27 -> 3.0202081 | AY26: =AY10/(AZ57+AZ56) -> 3.0375411 | AZ26: =AZ10/(BA57+BA56) -> 1.7862994 | BA26: =BA10/(BB57+BB56) -> 2.3917338 | BB26: =BB10/(BC57+BC56) -> 2.0297187 | BC26: =BC10/(BD57+BD56) -> 2.9418602 | BD26: =BD10/(BE57+BE56) -> 5.3595753 | BE26: =BE10/BH27 -> 2.3338658 | BH26: =BH10/BI27 -> 2.4324842 | BI26: =BI10/BJ27 -> 2.069479 | BJ26: =BJ10/BK27 -> 2.1548304 | BK26: =BK10/BL27 -> 2.9406585 | BL26: =BL10/BM27 -> 2.5009495 | BM26: =BM10/BN27 -> 2.0577587 | BN26: =BN10/BO27 -> 2.332053 | BV26: 0 | BW26: 0 | BX26: 0 | BY26: 0 | BZ26: 0 | CA26: 0 | CB26: 0 | CC26: 0 | CD26: 0 | CE26: 0 | CF26: 0 | CJ26: 0 | CK26: 0 | CL26: 0 | CM26: 0 | CN26: 0 | CO26: 0 | CP26: 0 | CQ26: 0 | CR26: 0 | CS26: 0 | CT26: 0 | CX26: 0 | CY26: 0 | CZ26: 0 | DA26: 0 | DB26: 0 | DC26: 0 | DD26: 0 | DE26: 0 | DF26: 0 | DG26: 0 | DH26: 0
A27: 6 | B27: Estimativa Vendas Comercial | D27: =SUM(D31:D54) -> 82250 | E27: =SUM(E31:E54) -> 117000 | F27: =SUM(F31:F54) -> 121750 | G27: =SUM(G31:G54) -> 150000 | H27: =SUM(H31:H54) -> 99500 | I27: =SUM(I31:I54) -> 102000 | J27: =SUM(J31:J54) -> 177632 | K27: =SUM(K31:K54) -> 178158 | ... P27: =SUM(P31:P54) -> 1617764 | R27: =R31+R55 -> 136177.34 | S27: =S31+S55 -> 143840.33 | T27: =T31+T55 -> 142553.77 | U27: =U31+U55 -> 19814.9 | V27: =V31+V55 -> 52085 | W27: =W31+W55 -> 70169.382 | X27: =X31+X55 -> 144463.33 | Y27: =Y31+Y55 -> 226547.08 | ... AC27: =AC31+AC55 -> 0 | AD27: =SUM(R27:AC27) -> 1418438.6 | AF27: =AF31+AF55 -> 128646 | AG27: =AG31+AG55 -> 177977 | AH27: =AH31+AH55 -> 73624 | AI27: =AI31+AI55 -> 89358 | AJ27: =AJ31+AJ55 -> 122134 | AK27: =AK31+AK55 -> 148560 | AL27: =AL31+AL55 -> 151995 | AM27: =AM31+AM55 -> 238903 | ... AQ27: =AQ31+AQ55 -> 97840 | AR27: =SUM(AF27:AQ27) -> 1874710.3 | AT27: =AT31+AT55 -> 152749.25 | AU27: =AU31+AU55 -> 168522.1 | AV27: =AV31+AV55 -> 154121.14 | AW27: =AW31+AW55 -> 159595.14 | AX27: =AX31+AX55 -> 120099.97 | AY27: =AY31+AY55 -> 138343.78 | AZ27: =AZ31+AZ55 -> 166673.78 | BA27: =BA31+BA55 -> 242442.3 | ... BD27: =BD31+BD55 -> 134555.59 | BE27: =BE31+BE56 -> 72686.613 | BF27: =SUM(AT27:BE27) -> 2006565.7 | BG27: =BF27-AR27 -> 131855.38 | BH27: =BH28+BH55 -> 152753 | BI27: =BI28+BI55 -> 146822.33 | BJ27: =BJ28+BJ55 -> 171546.07 | BK27: =BK28+BK55 -> 159771.74 | BL27: =BL28+BL55 -> 132496.85 | BM27: =BM28+BM55 -> 129906.26 | BN27: =BN28+BN55 -> 171383.56 | BO27: =BO28+BO56 -> 179550.38 | BP27: =BP28+BP56 -> 202053.75 | BQ27: =BQ28+BQ56 -> 163865 | BR27: =BR28+BR56 -> 175620.6 | BS27: 92285.6 | BT27: =SUM(BH27:BS27) -> 1878055.1 | BV27: =BV31+(BV56)*$CI$27 -> 161157.87 | BW27: =BW31+(BW56)*$CI$27 -> 155966.83 | BX27: =BX31+(BX56)*$CI$27 -> 196111.54 | BY27: =BY31+(BY56)*$CI$27 -> 159169.23 | BZ27: =BZ31+(BZ56)*$CI$27 -> 151482.39 | CA27: =CA31+(CA56)*$CI$27 -> 141442.13 | CB27: =CB31+(CB56)*$CI$27 -> 176986.21 | CC27: =CC31+(CC56)*$CI$27 -> 201301.09 | ... CG27: =CG31+(CG56)*$CI$27 -> 87483.817 | CH27: =SUM(BV27:CG27) -> 2030972.3 | CI27: 0.95 | CJ27: =CJ31+CJ65 -> 181422.94 | CK27: =CK31+CK65 -> 165852.67 | CL27: =CL31+CL65 -> 185796.68 | CM27: =CM31+CM65 -> 160056.66 | CN27: =CN31+CN65 -> 153801.95 | CO27: =CO31+CO65 -> 120180.88 | CP27: =CP31+CP65 -> 225720.09 | CQ27: =CQ31+CQ65 -> 206895.31 | ... CU27: =CU31+CU65 -> 103183.82 | CV27: =SUM(CJ27:CU27) -> 2151766.6 | CW27: 10% DE CRESCIMENTO | CX27: =CJ27*1.05 -> 190494.09 | CY27: =CK27*1.05 -> 174145.3 | CZ27: =CL27*1.05 -> 195086.51 | DA27: =CM27*1.05 -> 168059.49 | DB27: =CN27*1.05 -> 161492.05 | DC27: =CO27*1.05 -> 126189.92 | DD27: =CP27*1.05 -> 237006.09 | DE27: =CQ27*1.05 -> 217240.08 | ... DI27: =CU27*1.05 -> 108343.01 | DJ27: 1957097.2
B28: Estimativa de Venda para plano de produção | AY28: =AY31+AY56 -> 119777.78 | AZ28: =AZ31+AZ56 -> 150777.78 | BA28: =BA31+BA56 -> 233098.5 | BB28: =BB29/BB30 -> 210777.78 | BC28: =BC31+BC56 -> 249806.29 | BD28: =BD31+BD56*0.85 -> 122960.59 | BE28: =BE31+BE56*0.85 -> 66386.613 | BF28: =SUM(AT28:BE28) -> 1153585.3 | BH28: =BH29/BH30-0.1*BH29/BH30 -> 116600 | BI28: =BI29/BI30-0.1*BI29/BI30 -> 111533.33 | BJ28: =BJ29/BJ30-0.05*BJ29/BJ30 -> 135674.07 | BK28: =BK29/BK30-0.05*BK29/BK30 -> 121740.74 | BL28: =BL29/BL30-0.05*BL29/BL30 -> 93926.852 | BM28: =BM29/BM30-0.05*BM29/BM30 -> 90679.259 | BN28: =BN29/BN30-0.05*BN29/BN30 -> 130255.56 | BO28: =BO29/BO30-0.05*BO29/BO30 -> 150550.38 | BP28: =BP29/BP30-0.05*BP29/BP30 -> 161830.75 | BQ28: 127130 | BR28: 138687.6 | BS28: 43639.2 | BT28: =SUM(BH28:BS28) -> 1422247.7 | BV28: =BV31+BV55 -> 166555.78 | BW28: =BW31+BW55 -> 152835.37 | BX28: =BX31+BX55 -> 195319.21 | BY28: =BY31+BY55 -> 158396.19 | BZ28: =BZ31+BZ55 -> 152371.51 | CA28: =CA31+CA55 -> 147696.01 | CB28: =CB31+CB55 -> 189465.05 | CC28: =CC31+CC55 -> 202914.1 | ... CG28: =CG31+CG55 -> 88389.319 | CH28: =SUM(BV28:CG28) -> 2065409.9 | CI28: =(CH28-BT62)/BT62 -> 0.48621753 | CW28: =(CV28-CH62)/CH62 -> -1 | CX28: 166555.78 | CY28: 152835.37 | CZ28: 195319.21 | DA28: 158396.19 | DB28: 152371.51 | DC28: 147696.01 | DD28: 189465.05 | DE28: 202914.1 | DF28: 214499.62 | DG28: 217683 | DH28: 179284.72 | DI28: 88389.319 | DJ28: 2065409.9
B29: Estimativa Varejo em R$ | AN29: 6715000 | AO29: 6555000 | AP29: 2640000 | AQ29: 1302000 | AT29: 3264695 | AU29: 3863760 | AV29: 3429225 | AW29: 3525360 | AX29: 2509485 | AY29: 2829000 | AZ29: 3666000 | BA29: 5705000 | BB29: 5691000 | BC29: 5600000 | BD29: 2430000 | BE29: 800000 | BF29: =SUM(AT29:BE29) -> 43313525 | BH29: 3498000 | BI29: 3346000 | BJ29: 3856000 | BK29: 3460000 | BL29: 2669500 | BM29: 2577200 | BN29: 3702000 | BO29: 4278800.2 | BP29: 4599400.2 | BQ29: =BQ28*BQ30 -> 3432510 | BR29: 2954493.2 | BS29: 984831.07 | BT29: =SUM(BH29:BS29) -> 39358735 | BV29: =BV30*BV31 -> 3399704.6 | BW29: =BW30*BW31 -> 3264737.6 | BX29: =BX30*BX31 -> 4185000 | BY29: =BY30*BY31 -> 3348000 | BZ29: =BZ30*BZ31 -> 3074042.2 | CA29: =CA30*CA31 -> 2812995.4 | CB29: =CB30*CB31 -> 3737141.6 | CC29: =CC30*CC31 -> 4437000.7 | ... CG29: =CG30*CG31 -> 792579.23 | CH29: =SUM(BV29:CG29) -> 41966781 | CJ29: =CJ30*CJ31 -> 4023031.5 | CK29: =CK30*CK31 -> 3734347.7 | CL29: =CL30*CL31 -> 4223923.1 | CM29: =CM30*CM31 -> 3507679 | CN29: =CN30*CN31 -> 3217429.2 | CO29: =CO30*CO31 -> 2332522.6 | CP29: =CP30*CP31 -> 5138020.6 | CQ29: =CQ30*CQ31 -> 4640709 | ... CV29: =CV30*CV31 -> 46446711 | CX29: 3399704.6 | CY29: 3264737.6 | CZ29: 4185000 | DA29: 3348000 | DB29: 3074042.2 | DC29: 2812995.4 | DD29: 3737141.6 | DE29: 4437000.7 | DF29: 4710370.4 | DG29: 4744197 | DH29: 3461011.9 | DI29: 792579.23 | DJ29: 41966781
B30: Ticket Médio R$ | AN30: =30 -> 30 | AO30: =30 -> 30 | AP30: =30 -> 30 | AQ30: =30 -> 30 | AT30: 28 | AU30: 29 | AV30: 29 | AW30: 29 | AX30: 29 | AY30: 27 | AZ30: 27 | BA30: 27 | BB30: 27 | BC30: 26.07 | BD30: 26.07 | BE30: 26.07 | BH30: 27 | BI30: 27 | BJ30: 27 | BK30: 27 | BL30: 27 | BM30: 27 | BN30: 27 | BO30: 27 | BP30: 27 | BQ30: 27 | BR30: 27 | BS30: 27 | BV30: 26 | BW30: 26 | BX30: 26 | BY30: 26 | BZ30: 26 | CA30: 26 | CB30: 26 | CC30: 26 | CD30: 26 | CE30: 26 | CF30: 26 | CG30: 26 | CJ30: 26.32 | CK30: =CJ30 -> 26.32 | CL30: =CK30 -> 26.32 | CM30: =CL30 -> 26.32 | CN30: =CM30 -> 26.32 | CO30: =CN30 -> 26.32 | CP30: =CO30 -> 26.32 | CQ30: =CP30 -> 26.32 | CR30: =CQ30 -> 26.32 | ... CV30: =CU30 -> 26.32 | CX30: 26 | CY30: 26 | CZ30: 26 | DA30: 26 | DB30: 26 | DC30: 26 | DD30: 26 | DE30: 26 | DF30: 26 | DG30: 26 | DH30: 26 | DI30: 26
B31: Estimativa Varejo Multimarcas | D31: 82250 | E31: 117000 | F31: 121750 | G31: 150000 | H31: 99500 | I31: 102000 | J31: 177632 | K31: 178158 | L31: 199211 | M31: 229474 | N31: 122368 | O31: 38421 | P31: =SUM(D31:O31) -> 1617764 | R31: 115619.8 | S31: 123327.78 | T31: 128854 | U31: =126016*0.15 -> 18902.4 | V31: 35234 | W31: 56469.382 | X31: 118413.33 | Y31: 198797.08 | Z31: 242087.5 | AA31: 140000 | AB31: 0 | AC31: -45300 | AD31: =SUM(R31:AC31) -> 1132405.3 | AF31: 90146 | AG31: 155577 | AH31: 62953 | AI31: 73261 | AJ31: 91856 | AK31: 120000 | AL31: 110295 | AM31: 200203 | AN31: =AN29/AN30 -> 223833.33 | AO31: =AO29/AO30 -> 218500 | AP31: =AP29/AP30 -> 88000 | AQ31: =AQ29/AQ30 -> 43400 | AR31: =SUM(AF31:AQ31) -> 1478024.3 | AT31: =AT29/AT30 -> 116596.25 | AU31: =AU29/AU30 -> 133233.1 | AV31: =AV29/AV30 -> 118249.14 | AW31: =AW29/AW30 -> 121564.14 | AX31: =AX29/AX30 -> 86533.966 | AY31: =AY29/AY30 -> 104777.78 | AZ31: =AZ29/AZ30 -> 135777.78 | BA31: =BA29/BA30 -> 211296.3 | ... BE31: =BE29/BE30 -> 30686.613 | BF31: =SUM(AT31:BE31) -> 1577509.7 | BG31: =BF31-AR31 -> 99485.382 | BH31: =BH28 -> 116600 | BI31: =BI28 -> 111533.33 | BJ31: =BJ28 -> 135674.07 | BK31: =BK28 -> 121740.74 | BL31: =BL28 -> 93926.852 | BM31: =BM28 -> 90679.259 | BN31: =BN28 -> 130255.56 | BO31: =BO28 -> 150550.38 | ... BT31: =BT28 -> 1422247.7 | BV31: ='META EM PEÇAS'!S73 -> 130757.87 | BW31: ='META EM PEÇAS'!T73 -> 125566.83 | BX31: ='META EM PEÇAS'!U73 -> 160961.54 | BY31: ='META EM PEÇAS'!V73 -> 128769.23 | BZ31: ='META EM PEÇAS'!W73 -> 118232.39 | CA31: ='META EM PEÇAS'!X73 -> 108192.13 | CB31: ='META EM PEÇAS'!Y73 -> 143736.21 | CC31: ='META EM PEÇAS'!Z73 -> 170653.87 | ... CG31: ='META EM PEÇAS'!AD73 -> 30483.817 | CH31: 45 | CI31: =CH31*26 -> 1170 | CJ31: =BV62*1.19 -> 152850.74 | CK31: =BW62*1.19 -> 141882.51 | CL31: =BX62*1.19 -> 160483.4 | CM31: =BY62*1.19 -> 133270.48 | CN31: =BZ62*1.19 -> 122242.75 | CO31: =CA62*1.19 -> 88621.68 | CP31: =CB62*1.19 -> 195213.55 | CQ31: =CC62*1.19 -> 176318.73 | ... CU31: =CG62*1.19 -> 47560.73 | CV31: =SUM(CJ31:CU31) -> 1764692.6 | CW31: =CV31*26 -> 45882009 | CX31: 130757.87 | CY31: 125566.83 | CZ31: 160961.54 | DA31: 128769.23 | DB31: 118232.39 | DC31: 108192.13 | DD31: 143736.21 | DE31: 170653.87 | DF31: 181168.09 | DG31: 182469.12 | DH31: 133115.84 | DI31: 30483.817 | DJ31: 1614106.9
CJ32: =BV62 -> 128446 | CK32: =BW62 -> 119229 | CL32: =BX62 -> 134860 | CM32: =BY62 -> 111992 | CN32: =BZ62 -> 102725 | CO32: =CA62 -> 74472 | CP32: =CB62 -> 164045 | CQ32: =CC62 -> 148167 | ... CU32: =CG62 -> 39967 | CV32: =SUM(CJ32:CU32) -> 1482935
CJ33: =(CJ31-CJ32)/CJ32 -> 0.19 | CK33: =(CK31-CK32)/CK32 -> 0.19 | CL33: =(CL31-CL32)/CL32 -> 0.19 | CM33: =(CM31-CM32)/CM32 -> 0.19 | CN33: =(CN31-CN32)/CN32 -> 0.19 | CO33: =(CO31-CO32)/CO32 -> 0.19 | CP33: =(CP31-CP32)/CP32 -> 0.19 | CQ33: =(CQ31-CQ32)/CQ32 -> 0.19 | ... CU33: =(CU31-CU32)/CU32 -> 0.19
A34: 1 | B34: Loja Maraponga | P34: =SUM(D34:O34) -> 0 | R34: 7017.5439 | S34: 7017.5439 | T34: =7017.54385964912/2 -> 3508.7719 | U34: =96*U7 -> 96 | V34: 3000 | W34: 7200 | X34: 8500 | Y34: 8500 | Z34: 8500 | AA34: 9000 | AB34: 9500 | AC34: 8500 | AD34: =SUM(R34:AC34) -> 80339.86 | AF34: 8000 | AG34: 4000 | AH34: 5673 | AI34: 4500 | AJ34: 7892 | AK34: 6400 | AL34: 8000 | AM34: 8000 | AN34: 8000 | AO34: 8000 | AP34: 8800 | AQ34: 6400 | AR34: =SUM(AF34:AQ34) -> 83665 | AT34: 4861 | AU34: 5809 | AV34: 5072 | AW34: 4725 | AX34: 5832 | AY34: 5832 | AZ34: 5567 | BA34: 5567 | BB34: 5832 | BC34: 6892 | BD34: 7422 | BE34: 4241 | BF34: =SUM(AT34:BE34) -> 67652 | BG34: =BF34/AR34-1 -> -0.19139425 | BT34: 36051 | BV34: 4782.99 | BW34: 2945.31 | BX34: ='META EM PEÇAS'!U26-('META EM PEÇAS'!U26*0.05) -> 7080.369 | BY34: ='META EM PEÇAS'!V26-('META EM PEÇAS'!V26*0.05) -> 4355.655 | BZ34: ='META EM PEÇAS'!W26-('META EM PEÇAS'!W26*0.05) -> 5839.935 | CA34: ='META EM PEÇAS'!X26-('META EM PEÇAS'!X26*0.05) -> 5900.8965 | CB34: ='META EM PEÇAS'!Y26-('META EM PEÇAS'!Y26*0.05) -> 5279.796 | CC34: ='META EM PEÇAS'!Z26-('META EM PEÇAS'!Z26*0.05) -> 4897.2405 | CD34: ='META EM PEÇAS'!AA26-('META EM PEÇAS'!AA26*0.05) -> 5018.28 | CE34: ='META EM PEÇAS'!AB26-('META EM PEÇAS'!AB26*0.05) -> 4641.0255 | ... CG34: ='META EM PEÇAS'!AD26-('META EM PEÇAS'!AD26*0.05) -> 3929.808 | CH34: 4136.64 | CJ34: 4782.99 | CK34: 2945.31 | CL34: 7080.369 | CM34: 4355.655 | CN34: 5839.935 | CO34: 5900.8965 | CP34: 5279.796 | CQ34: 4897.2405 | CR34: 5018.28 | CS34: 4641.0255 | CT34: 6521.1135 | CU34: 3929.808 | CV34: 4136.64 | CX34: 4782.99 | CY34: 2945.31 | CZ34: 7080.369 | DA34: 4355.655 | DB34: 5839.935 | DC34: 5900.8965 | DD34: 5279.796 | DE34: 4897.2405 | DF34: 5018.28 | DG34: 4641.0255 | DH34: 6521.1135 | DI34: 3929.808 | DJ34: 4136.64
A35: 2 | B35: Loja Iguatemi | P35: =SUM(D35:O35) -> 0 | R35: 2909 | S35: 2545 | T35: =2727/1.2 -> 2272.5 | U35: =2*U7 -> 2 | V35: 500 | W35: 1300 | X35: 3200 | Y35: 3200 | Z35: 3600 | AA35: 3600 | AB35: 3600 | AC35: 4500 | AD35: =SUM(R35:AC35) -> 31228.5 | AF35: 4000 | AG35: 1500 | AH35: 189 | AI35: 1842 | AJ35: 3764 | AK35: 3200 | AL35: 6000 | AM35: 5000 | AN35: 5000 | AO35: 5000 | AP35: 5000 | AQ35: 9000 | AR35: =SUM(AF35:AQ35) -> 49495 | AT35: 5468 | AU35: 5468 | AV35: 6249 | AW35: 6249 | AX35: 3923 | AY35: 3923 | AZ35: 3745 | BA35: 3745 | BB35: 3923 | BC35: 4636 | BD35: 4993 | BE35: 7133 | BF35: =SUM(AT35:BE35) -> 59455 | BG35: =BF35/AR35-1 -> 0.20123245 | BT35: 40562 | BV35: 4442.61 | BW35: 3433.56 | BX35: ='META EM PEÇAS'!U27-('META EM PEÇAS'!U27*0.05) -> 3860.0115 | BY35: ='META EM PEÇAS'!V27-('META EM PEÇAS'!V27*0.05) -> 3578.175 | BZ35: ='META EM PEÇAS'!W27-('META EM PEÇAS'!W27*0.05) -> 4015.5075 | CA35: ='META EM PEÇAS'!X27-('META EM PEÇAS'!X27*0.05) -> 4835.3955 | CB35: ='META EM PEÇAS'!Y27-('META EM PEÇAS'!Y27*0.05) -> 5815.197 | CC35: ='META EM PEÇAS'!Z27-('META EM PEÇAS'!Z27*0.05) -> 3888.2835 | CD35: ='META EM PEÇAS'!AA27-('META EM PEÇAS'!AA27*0.05) -> 4032.294 | CE35: ='META EM PEÇAS'!AB27-('META EM PEÇAS'!AB27*0.05) -> 4375.092 | ... CG35: ='META EM PEÇAS'!AD27-('META EM PEÇAS'!AD27*0.05) -> 7897.6065 | CH35: =SUM(BV35:CG35) -> 55778.656 | CJ35: 4442.61 | CK35: 3433.56 | CL35: 3860.0115 | CM35: 3578.175 | CN35: 4015.5075 | CO35: 4835.3955 | CP35: 5815.197 | CQ35: 3888.2835 | CR35: 4032.294 | CS35: 4375.092 | CT35: 5604.924 | CU35: 7897.6065 | CV35: 55778.656 | CX35: 4442.61 | CY35: 3433.56 | CZ35: 3860.0115 | DA35: 3578.175 | DB35: 4015.5075 | DC35: 4835.3955 | DD35: 5815.197 | DE35: 3888.2835 | DF35: 4032.294 | DG35: 4375.092 | DH35: 5604.924 | DI35: 7897.6065 | DJ35: 55778.656
A36: 3 | B36: Loja Monsenhor Tabosa | P36: =SUM(D36:O36) -> 0 | R36: 746 | S36: 653 | T36: 700 | U36: 0 | V36: 200 | W36: 400 | X36: 900 | Y36: 900 | Z36: 900 | AA36: 900 | AB36: 900 | AC36: 1200 | AD36: =SUM(R36:AC36) -> 8399 | AF36: 1800 | AG36: 1200 | AH36: 230 | AI36: 472 | AJ36: 1495 | AK36: 1200 | AL36: 1500 | AM36: 1500 | AN36: 1500 | AO36: 1500 | AP36: 1650 | AQ36: 2400 | AR36: =SUM(AF36:AQ36) -> 16447 | AT36: 2438 | AU36: 1501 | AV36: 1566 | AW36: 2127 | AX36: 1928 | AY36: 1928 | AZ36: 1840 | BA36: 1840 | BB36: 1928 | BC36: 2278 | BD36: 2454 | BE36: 3505 | BF36: =SUM(AT36:BE36) -> 25333 | BG36: =BF36/AR36-1 -> 0.5402809 | BT36: 7784 | BV36: 451 | BW36: 348.6 | BX36: ='META EM PEÇAS'!U28-('META EM PEÇAS'!U28*0.05) -> 391.97 | BY36: ='META EM PEÇAS'!V28-('META EM PEÇAS'!V28*0.05) -> 363.28 | BZ36: ='META EM PEÇAS'!W28-('META EM PEÇAS'!W28*0.05) -> 407.55 | CA36: ='META EM PEÇAS'!X28-('META EM PEÇAS'!X28*0.05) -> 490.77 | CB36: ='META EM PEÇAS'!Y28-('META EM PEÇAS'!Y28*0.05) -> 590.33 | CC36: ='META EM PEÇAS'!Z28-('META EM PEÇAS'!Z28*0.05) -> 394.63 | CD36: ='META EM PEÇAS'!AA28-('META EM PEÇAS'!AA28*0.05) -> 409.26 | CE36: ='META EM PEÇAS'!AB28-('META EM PEÇAS'!AB28*0.05) -> 444.22 | ... CG36: ='META EM PEÇAS'!AD28-('META EM PEÇAS'!AD28*0.05) -> 801.8 | CH36: =SUM(BV36:CG36) -> 5662.46 | CJ36: 451 | CK36: 348.6 | CL36: 391.97 | CM36: 363.28 | CN36: 407.55 | CO36: 490.77 | CP36: 590.33 | CQ36: 394.63 | CR36: 409.26 | CS36: 444.22 | CT36: 569.05 | CU36: 801.8 | CV36: 5662.46 | CX36: 451 | CY36: 348.6 | CZ36: 391.97 | DA36: 363.28 | DB36: 407.55 | DC36: 490.77 | DD36: 590.33 | DE36: 394.63 | DF36: 409.26 | DG36: 444.22 | DH36: 569.05 | DI36: 801.8 | DJ36: 5662.46
A37: 4 | B37: Loja North Shopping | P37: =SUM(D37:O37) -> 0 | R37: 1455 | S37: =2036 -> 2036 | T37: =2182/2 -> 1091 | U37: 0 | V37: 200 | W37: 900 | X37: 1600 | Y37: 1600 | Z37: 1600 | AA37: 1600 | AB37: 2200 | AC37: 2500 | AD37: =SUM(R37:AC37) -> 16782 | AF37: 2200 | AG37: 1500 | AH37: 121 | AI37: 565 | AJ37: 1514 | AK37: 1760 | AL37: 1800 | AM37: 2200 | AN37: 2200 | AO37: 2200 | AP37: 2420 | AQ37: 3520 | AR37: =SUM(AF37:AQ37) -> 22000 | AT37: 1529 | AU37: 1516 | AV37: 1586 | AW37: 1979 | AX37: 1283 | AY37: 1283 | AZ37: 1224 | BA37: 1224 | BB37: 1283 | BC37: 1516 | BD37: 1632 | BE37: 2332 | BF37: =SUM(AT37:BE37) -> 18387 | BG37: =BF37/AR37-1 -> -0.16422727 | BT37: 9018 | BV37: 1143.9 | BW37: 884.43 | BX37: ='META EM PEÇAS'!U29-('META EM PEÇAS'!U29*0.05) -> 993.9375 | BY37: ='META EM PEÇAS'!V29-('META EM PEÇAS'!V29*0.05) -> 921.4905 | BZ37: ='META EM PEÇAS'!W29-('META EM PEÇAS'!W29*0.05) -> 1033.695 | CA37: ='META EM PEÇAS'!X29-('META EM PEÇAS'!X29*0.05) -> 1244.8515 | CB37: ='META EM PEÇAS'!Y29-('META EM PEÇAS'!Y29*0.05) -> 1497.5325 | CC37: ='META EM PEÇAS'!Z29-('META EM PEÇAS'!Z29*0.05) -> 1001.0055 | CD37: ='META EM PEÇAS'!AA29-('META EM PEÇAS'!AA29*0.05) -> 1038.1125 | CE37: ='META EM PEÇAS'!AB29-('META EM PEÇAS'!AB29*0.05) -> 1126.4625 | ... CG37: ='META EM PEÇAS'!AD29-('META EM PEÇAS'!AD29*0.05) -> 2033.817 | CH37: =SUM(BV37:CG37) -> 14362.873 | CJ37: 1143.9 | CK37: 884.43 | CL37: 993.9375 | CM37: 921.4905 | CN37: 1033.695 | CO37: 1244.8515 | CP37: 1497.5325 | CQ37: 1001.0055 | CR37: 1038.1125 | CS37: 1126.4625 | CT37: 1443.639 | CU37: 2033.817 | CV37: 14362.873 | CX37: 1143.9 | CY37: 884.43 | CZ37: 993.9375 | DA37: 921.4905 | DB37: 1033.695 | DC37: 1244.8515 | DD37: 1497.5325 | DE37: 1001.0055 | DF37: 1038.1125 | DG37: 1126.4625 | DH37: 1443.639 | DI37: 2033.817 | DJ37: 14362.873
A38: 5 | B38: Loja Dom Luis | P38: =SUM(D38:O38) -> 0 | R38: 1353 | S38: 1184 | T38: 1268 | U38: =10*U7 -> 10 | V38: =10*V7 -> 120 | W38: 600 | X38: 1600 | Y38: 1600 | Z38: 1600 | AA38: 1600 | AB38: 1600 | AC38: 2200 | AD38: =SUM(R38:AC38) -> 14735 | AF38: 1800 | AG38: 1200 | AH38: 181 | AI38: 628 | AJ38: 1169 | AK38: 960 | AL38: 1500 | AM38: 1200 | AN38: 1200 | AO38: 1200 | AP38: 1320 | AQ38: 1920 | AR38: =SUM(AF38:AQ38) -> 14278 | AT38: 1496 | AU38: 1200 | AV38: 1227 | AW38: 1655 | AX38: 1141 | AY38: 1141 | AZ38: 1089 | BA38: 1089 | BB38: 1141 | BC38: 1349 | BD38: 1453 | BE38: 2075 | BF38: =SUM(AT38:BE38) -> 16056 | BG38: =BF38/AR38-1 -> 0.12452724 | BT38: 10591 | BV38: 1474.98 | BW38: 1140.18 | BX38: ='META EM PEÇAS'!U30-('META EM PEÇAS'!U30*0.05) -> 1281.9585 | BY38: ='META EM PEÇAS'!V30-('META EM PEÇAS'!V30*0.05) -> 1188.3075 | BZ38: ='META EM PEÇAS'!W30-('META EM PEÇAS'!W30*0.05) -> 1333.2015 | CA38: ='META EM PEÇAS'!X30-('META EM PEÇAS'!X30*0.05) -> 1606.203 | CB38: ='META EM PEÇAS'!Y30-('META EM PEÇAS'!Y30*0.05) -> 1931.331 | CC38: ='META EM PEÇAS'!Z30-('META EM PEÇAS'!Z30*0.05) -> 1291.677 | CD38: ='META EM PEÇAS'!AA30-('META EM PEÇAS'!AA30*0.05) -> 1339.386 | CE38: ='META EM PEÇAS'!AB30-('META EM PEÇAS'!AB30*0.05) -> 1453.3575 | ... CG38: ='META EM PEÇAS'!AD30-('META EM PEÇAS'!AD30*0.05) -> 2623.1115 | CH38: =SUM(BV38:CG38) -> 18525.228 | CJ38: 1474.98 | CK38: 1140.18 | CL38: 1281.9585 | CM38: 1188.3075 | CN38: 1333.2015 | CO38: 1606.203 | CP38: 1931.331 | CQ38: 1291.677 | CR38: 1339.386 | CS38: 1453.3575 | CT38: 1861.5345 | CU38: 2623.1115 | CV38: 18525.228 | CX38: 1474.98 | CY38: 1140.18 | CZ38: 1281.9585 | DA38: 1188.3075 | DB38: 1333.2015 | DC38: 1606.203 | DD38: 1931.331 | DE38: 1291.677 | DF38: 1339.386 | DG38: 1453.3575 | DH38: 1861.5345 | DI38: 2623.1115 | DJ38: 18525.228
A39: 6 | B39: Loja Parangaba | P39: =SUM(D39:O39) -> 0 | R39: 1455 | S39: 1273 | T39: 1364 | U39: 0 | V39: 200 | W39: 800 | X39: 1600 | Y39: 1600 | Z39: 1600 | AA39: 1600 | AB39: 1800 | AC39: 2400 | AD39: =SUM(R39:AC39) -> 15692 | AF39: 1500 | AG39: 1200 | AH39: 127 | AI39: 426 | AJ39: 1063 | AK39: 960 | AL39: 1500 | AM39: 1200 | AN39: 1200 | AO39: 1200 | AP39: 1320 | AQ39: 1920 | AR39: =SUM(AF39:AQ39) -> 13616 | AT39: 1222 | AU39: 1200 | AV39: 1117 | AW39: 1463 | AX39: 1087 | AY39: 1087 | AZ39: 1038 | BA39: 1038 | BB39: 1087 | BC39: 1285 | BD39: 1384 | BE39: 1977 | BF39: =SUM(AT39:BE39) -> 14985 | BG39: =BF39/AR39-1 -> 0.10054348 | BT39: 10087 | BV39: 1214.58 | BW39: 939.3 | BX39: ='META EM PEÇAS'!U31-('META EM PEÇAS'!U31*0.05) -> 1055.7825 | BY39: ='META EM PEÇAS'!V31-('META EM PEÇAS'!V31*0.05) -> 978.0345 | BZ39: ='META EM PEÇAS'!W31-('META EM PEÇAS'!W31*0.05) -> 1098.1905 | CA39: ='META EM PEÇAS'!X31-('META EM PEÇAS'!X31*0.05) -> 1322.5995 | CB39: ='META EM PEÇAS'!Y31-('META EM PEÇAS'!Y31*0.05) -> 1590.3 | CC39: ='META EM PEÇAS'!Z31-('META EM PEÇAS'!Z31*0.05) -> 1062.8505 | CD39: ='META EM PEÇAS'!AA31-('META EM PEÇAS'!AA31*0.05) -> 1102.608 | CE39: ='META EM PEÇAS'!AB31-('META EM PEÇAS'!AB31*0.05) -> 1196.259 | ... CG39: ='META EM PEÇAS'!AD31-('META EM PEÇAS'!AD31*0.05) -> 2160.1575 | CH39: =SUM(BV39:CG39) -> 15253.534 | CJ39: 1214.58 | CK39: 939.3 | CL39: 1055.7825 | CM39: 978.0345 | CN39: 1098.1905 | CO39: 1322.5995 | CP39: 1590.3 | CQ39: 1062.8505 | CR39: 1102.608 | CS39: 1196.259 | CT39: 1532.8725 | CU39: 2160.1575 | CV39: 15253.534 | CX39: 1214.58 | CY39: 939.3 | CZ39: 1055.7825 | DA39: 978.0345 | DB39: 1098.1905 | DC39: 1322.5995 | DD39: 1590.3 | DE39: 1062.8505 | DF39: 1102.608 | DG39: 1196.259 | DH39: 1532.8725 | DI39: 2160.1575 | DJ39: 15253.534
A40: 7 | B40: Loja Rio Mar | P40: =SUM(D40:O40) -> 0 | R40: 2000 | S40: =2182 -> 2182 | T40: =2455/2 -> 1227.5 | U40: =4*U7 -> 4 | V40: 200 | W40: 700 | X40: 1600 | Y40: 1600 | Z40: 1600 | AA40: 1600 | AB40: 2500 | AC40: 3200 | AD40: =SUM(R40:AC40) -> 18413.5 | AF40: 2600 | AG40: 1000 | AH40: 195 | AI40: 844 | AJ40: 1973 | AK40: 1840 | AL40: 2000 | AM40: 2300 | AN40: 2300 | AO40: 2300 | AP40: 2530 | AQ40: 3680 | AR40: =SUM(AF40:AQ40) -> 23562 | AT40: 1888 | AU40: 1414 | AV40: 2073 | AW40: 2338 | AX40: 1857 | AY40: 1857 | AZ40: 1772 | BA40: 1772 | BB40: 1857 | BC40: 2194 | BD40: 2363 | BE40: 3376 | BF40: =SUM(AT40:BE40) -> 24761 | BG40: =BF40/AR40-1 -> 0.050887021 | BT40: 22941 | BV40: 3211.29 | BW40: 2482.17 | BX40: ='META EM PEÇAS'!U32-('META EM PEÇAS'!U32*0.05) -> 2790.093 | BY40: ='META EM PEÇAS'!V32-('META EM PEÇAS'!V32*0.05) -> 2586.0045 | BZ40: ='META EM PEÇAS'!W32-('META EM PEÇAS'!W32*0.05) -> 2902.2975 | CA40: ='META EM PEÇAS'!X32-('META EM PEÇAS'!X32*0.05) -> 3495.126 | CB40: ='META EM PEÇAS'!Y32-('META EM PEÇAS'!Y32*0.05) -> 4203.693 | CC40: ='META EM PEÇAS'!Z32-('META EM PEÇAS'!Z32*0.05) -> 2810.4135 | CD40: ='META EM PEÇAS'!AA32-('META EM PEÇAS'!AA32*0.05) -> 2914.6665 | CE40: ='META EM PEÇAS'!AB32-('META EM PEÇAS'!AB32*0.05) -> 3162.93 | ... CG40: ='META EM PEÇAS'!AD32-('META EM PEÇAS'!AD32*0.05) -> 5709.177 | CH40: =SUM(BV40:CG40) -> 40319.592 | CJ40: 3211.29 | CK40: 2482.17 | CL40: 2790.093 | CM40: 2586.0045 | CN40: 2902.2975 | CO40: 3495.126 | CP40: 4203.693 | CQ40: 2810.4135 | CR40: 2914.6665 | CS40: 3162.93 | CT40: 4051.731 | CU40: 5709.177 | CV40: 40319.592 | CX40: 3211.29 | CY40: 2482.17 | CZ40: 2790.093 | DA40: 2586.0045 | DB40: 2902.2975 | DC40: 3495.126 | DD40: 4203.693 | DE40: 2810.4135 | DF40: 2914.6665 | DG40: 3162.93 | DH40: 4051.731 | DI40: 5709.177 | DJ40: 40319.592
...

Sheet Plano mestre 95 % 2025 5% - (3)
R1: PLANEJAMENTO FABRICA | AF1: PLANEJAMENTO FABRICA | AT1: PLANEJAMENTO FABRICA | BH1: PLANEJAMENTO FABRICA | BV1: PLANEJAMENTO FABRICA | CH1: Férias 18/12 - 29/12 | CJ1: PLANEJAMENTO FABRICA | CX1: PLANEJAMENTO FABRICA
D2: 2019 | R2: 2020 | AF2: 2021 | AT2: 2022 | BH2: 2023 | BV2: 2024 | CH2: COMPENSAÇÃO 30 ,31 ,02 e 03 | CJ2: /--------------------------------------------2025 | CX2: 2026
A3: Dias Uteis Produção | C3: =A3 -> Dias Uteis Produção | CH3: 12 dias de férias | CJ3: 23 | CK3: 20 | CL3: 21 | CM3: 22 | CN3: 22 | CO3: 21 | CP3: 23 | CQ3: 21 | CR3: 21 | CS3: 23 | CT3: 20 | CU3: 13 | CX3: 23 | CY3: 20 | CZ3: 21 | DA3: 22 | DB3: 22 | DC3: 21 | DD3: 23 | DE3: 21 | DF3: 21 | DG3: 23 | DH3: 20 | DI3: 13
A4: (-) FÉRIAS | C4: =A4 -> (-) FÉRIAS | CH4: 4 dias de compensação | CJ4: 3 | CL4: 1.5 | CX4: 3 | CY4: 5
A5: (+) SABADO | C5: =A5 -> (+) SABADO | CH5: dias de compensação 9/11 , 23/11 , 7/12 e 14/12 | CJ5: 2 | CK5: 3 | CL5: 1.5 | CM5: 0 | CN5: 0 | CO5: 1.5 | CP5: 1 | CQ5: 1.5 | CR5: 1.5 | CS5: 1.5 | CT5: 0 | DA5: 0 | DB5: 0 | DC5: 0 | DD5: 0 | DE5: 0 | DF5: 0 | DG5: 1 | DH5: 0
A6: (-)FERIADO | C6: =A6 -> (-)FERIADO | CG6: 2 grupos a partir de dezembro | CL6: 2 | CM6: 2 | CN6: 1 | CO6: 1 | CR6: 1 | CS6: 1 | CT6: 1 | CZ6: 2 | DA6: 2 | DB6: 1 | DC6: 1 | DF6: 1 | DG6: 1 | DH6: 1
A7: Dias Trabalhados | C7: =A7 -> Dias Trabalhados | D7: 16 | E7: 21 | F7: 18 | G7: 21 | H7: 22 | I7: 19 | J7: 23 | K7: 21 | L7: 21 | M7: 26 | N7: 24 | O7: 15 | R7: 22 | S7: 20 | T7: 14 | U7: 1 | V7: 12 | W7: 22 | X7: 23 | Y7: 21 | Z7: 21 | AA7: 21 | AB7: 20 | AC7: 17 | AF7: 18 | AG7: 20 | AH7: 20 | AI7: 20 | AJ7: 22 | AK7: 20 | AL7: 22 | AM7: 22 | AN7: 21 | AO7: 20 | AP7: 20 | AQ7: 12 | AT7: 19 | AU7: 19 | AV7: 18 | AW7: 19 | AX7: 22 | AY7: 21 | AZ7: 21 | BA7: 22 | BB7: 22 | BC7: 21 | BD7: 20 | BE7: 10 | BH7: 20 | BI7: 17 | BJ7: 23 | BK7: 18 | BL7: 22 | BM7: 23 | BN7: 21 | BO7: 21 | BP7: 20 | BQ7: 21 | BR7: 20 | BS7: 14 | BT7: 20 | BV7: 19 | BW7: 19 | BX7: 21 | BY7: =22+2 -> 24 | BZ7: =21+2 -> 23 | CA7: =20+2 -> 22 | CB7: =23+2 -> 25 | CC7: =21+3 -> 24 | CD7: =21+3 -> 24 | CE7: =23+1 -> 24 | CF7: =19+3 -> 22 | CG7: =12+1 -> 13 | CJ7: =CJ3+CJ5-CJ6-CJ4 -> 22 | CK7: =CK3+CK5-CK6-CK4 -> 23 | CL7: 19 | CM7: =CM3+CM5-CM6-CM4 -> 20 | CN7: =CN3+CN5-CN6-CN4 -> 21 | CO7: =CO3+CO5-CO6-CO4 -> 21.5 | CP7: =CP3+CP5-CP6 -> 24 | CQ7: =CQ3+CQ5-CQ6 -> 22.5 | CR7: =CR3+CR5-CR6 -> 21.5 | CS7: =CS3+CS5-CS6 -> 23.5 | CT7: =CT3+CT5-CT6 -> 19 | CU7: =CU3+CU5-CU6 -> 13 | CX7: =CX3+CX5-CX6-CX4 -> 20 | CY7: =CY3+CY5-CY6-CY4 -> 15 | CZ7: =CZ3+CZ5-CZ6-CZ4 -> 19 | DA7: =DA3+DA5-DA6-DA4 -> 20 | DB7: =DB3+DB5-DB6-DB4 -> 21 | DC7: =DC3+DC5-DC6-DC4 -> 20 | DD7: =DD3+DD5-DD6 -> 23 | DE7: =DE3+DE5-DE6 -> 21 | DF7: =DF3+DF5-DF6 -> 20 | DG7: =DG3+DG5-DG6 -> 23 | DH7: =DH3+DH5-DH6 -> 19 | DI7: =DI3+DI5-DI6 -> 13
D8: JAN | E8: FEV | F8: MAR | G8: ABR | H8: MAI | I8: JUN | J8: JUL | K8: AGO | L8: SET | M8: OUT | N8: NOV | O8: DEZ | P8: TOTAL | R8: JAN | S8: FEV | T8: MAR | U8: ABR | V8: MAI | W8: JUN | X8: JUL | Y8: AGO | Z8: SET | AA8: OUT | AB8: NOV | AC8: DEZ | AD8: TOTAL | AF8: JAN | AG8: FEV | AH8: MAR | AI8: ABR | AJ8: MAI | AK8: JUN | AL8: JUL | AM8: AGO | AN8: SET | AO8: OUT | AP8: NOV | AQ8: DEZ | AR8: TOTAL | AT8: JAN | AU8: FEV | AV8: MAR | AW8: ABR | AX8: MAI | AY8: JUN | AZ8: JUL | BA8: AGO | BB8: SET | BC8: OUT | BD8: NOV | BE8: DEZ | BF8: TOTAL | BH8: JAN | BI8: FEV | BJ8: MAR | BK8: ABR | BL8: MAI | BM8: JUN | BN8: JUL | BO8: AGO | BP8: SET | BQ8: OUT | BR8: NOV | BS8: DEZ | BT8: TOTAL | BV8: JAN | BW8: FEV | BX8: MAR | BY8: ABR | BZ8: MAI | CA8: JUN | CB8: JUL | CC8: AGO | CD8: SET | CE8: OUT | CF8: NOV | CG8: DEZ | CH8: TOTAL | CJ8: JAN | CK8: FEV | CL8: MAR | CM8: ABR | CN8: MAI | CO8: JUN | CP8: JUL | CQ8: AGO | CR8: SET | CS8: OUT | CT8: NOV | CU8: DEZ | CV8: TOTAL | CX8: JAN | CY8: FEV | CZ8: MAR | DA8: ABR | DB8: MAI | DC8: JUN | DD8: JUL | DE8: AGO | DF8: SET | DG8: OUT | DH8: NOV | DI8: DEZ | DJ8: TOTAL
CI9: redução de meta | CW9: redução de meta
A10: ESTOQUE FÍSICO | B10: Total (1+2) DISPONÍVEL TOTAL | D10: =SUM(D15:D17) -> 304786 | E10: =SUM(E15:E17) -> 311986 | F10: =SUM(F15:F17) -> 328231 | G10: =SUM(G15:G17) -> 317873 | H10: =SUM(H15:H17) -> 347196 | I10: =SUM(I15:I17) -> 402253 | J10: =SUM(J15:J17) -> 454488 | K10: =SUM(K15:K17) -> 447182 | ... O10: =SUM(O15:O17) -> 188264 | R10: =SUM(R15:R17) -> 283359 | S10: =SUM(S15:S17) -> 342718 | T10: =SUM(T15:T17) -> 313212 | U10: =SUM(U15:U17) -> 298093 | V10: =SUM(V15:V17) -> 206617 | W10: =SUM(W15:W17) -> 235875 | X10: =SUM(X15:X17) -> 360135 | Y10: =SUM(Y15:Y17) -> 361665 | ... AC10: =SUM(AC15:AC17) -> 197551 | AF10: =SUM(AF15:AF19) -> 255339 | AG10: =SUM(AG15:AG19) -> 292621 | AH10: =SUM(AH15:AH19) -> 397976 | AI10: =SUM(AI15:AI19) -> 388165 | AJ10: =SUM(AJ15:AJ19) -> 409301 | AK10: =SUM(AK15:AK19) -> 490913 | AL10: =SUM(AL15:AL19) -> 563229 | AM10: =SUM(AM15:AM19) -> 559169 | ... AQ10: =SUM(AQ15:AQ19) -> 531679 | AR10: =AQ10 -> 531679 | AT10: =SUM(AT15:AT19) -> 471378 | AU10: =SUM(AU15:AU19) -> 473307 | AV10: =SUM(AV15:AV19) -> 412518 | AW10: =SUM(AW15:AW19) -> 398039 | AX10: =SUM(AX15:AX19) -> 417827 | AY10: =SUM(AY15:AY19) -> 507968 | AZ10: =SUM(AZ15:AZ19) -> 477530 | BA10: =SUM(BA15:BA19) -> 520708 | ... BE10: =SUM(BE15:BE19) -> 356505 | BF10: =BE10 -> 356505 | BH10: =SUM(BH15:BH19) -> 357143 | BI10: =SUM(BI15:BI19) -> 355011 | BJ10: =SUM(BJ15:BJ19) -> 344281 | BK10: =SUM(BK15:BK19) -> 389628 | BL10: =SUM(BL15:BL19) -> 324889 | BM10: =SUM(BM15:BM19) -> 352666 | BN10: =SUM(BN15:BN19) -> 418721 | BO10: =SUM(BO15:BO19) -> 356602 | ... BR10: =SUM(BR15:BR19) -> 228035 | BS10: =BS15+BS16+BS19 -> 201165 | BT10: =BS10 -> 201165 | BV10: =BV11+BV16+BV19 -> 247713 | BW10: =BW11+BW16+BW19 -> 278707 | BX10: =BX11+BX16+BX19 -> 281829 | BY10: =BY11+BY16+BY19 -> 317753 | BZ10: =BZ11+BZ16+BZ19 -> 270339 | CA10: =CA11+CA16+CA19 -> 310383 | CB10: =CB11+CB16+CB19 -> 328365 | CC10: =CC11+CC16+CC19 -> 333476 | ... CG10: =CG11+CG16+CG19 -> 182266 | CH10: =CH15+CH16+CH19 -> 161447 | CJ10: =CH10+CJ71-CJ27 -> 145024.06 | CK10: =CJ10+CK71-CK27 -> 167771.39 | CL10: =CK10+CL71-CL27 -> 152974.71 | CM10: =CL10+CM71-CM27 -> 172918.05 | CN10: =CM10+CN71-CN27 -> 208116.1 | CO10: =CN10+CO71-CO27 -> 281435.22 | CP10: =CO10+CP71-CP27 -> 271715.13 | CQ10: =CP10+CQ71-CQ27 -> 271819.82 | CR10: =CQ10+CR71-CR27 -> 212966.18 | ... CU10: =CT10+CU71-CU27 -> 228180.35 | CV10: 116080.11 | CX10: =CV10+CX71-CX27 -> 109586.02 | CY10: =CX10+CY71-CY27 -> 73440.716 | CZ10: =CY10+CZ71-CZ27 -> 53154.202 | DA10: =CZ10+DA71-DA27 -> 69094.709 | DB10: =DA10+DB71-DB27 -> 100802.66 | DC10: =DB10+DC71-DC27 -> 158612.74 | DD10: =DC10+DD71-DD27 -> 133206.64 | DE10: =DD10+DE71-DE27 -> 109166.57 | DF10: =DE10+DF71-DF27 -> 23680.246 | ... DI10: =DH10+DI71-DI27 -> 9525.1244 | DJ10: 116080.11
A11: 0 | B11: ESTOQUE FISICO EM LINHA | BV11: 204006 | BW11: 241182 | BX11: 245950 | BY11: 281974 | BZ11: 202865 | CA11: 240895 | CB11: 273565 | CC11: 288981 | CD11: 273990 | CE11: 237556 | CF11: 168313 | CG11: 150819 | CH11: =CG11 -> 150819 | CJ11: 205037 | CK11: 230430 | CL11: 234343 | CM11: 262404
A12: 0 | B12: PEDIDOS EM CARTEIRA | BV12: 80956 | BW12: 110544 | BX12: 134506 | BY12: 127959 | BZ12: 66136 | CA12: 72582 | CB12: 94286 | CC12: 133081 | CD12: 148174 | CE12: 154201 | CF12: 97365 | CG12: 30184 | CJ12: 132209 | CK12: 180000 | CL12: 177643 | CM12: 148159
A13: 0 | B13: PROCESSO | CJ13: 150321 | CK13: 133602 | CL13: 135672 | CM13: 127653
A14: 0 | B14: ESTOQUE NEGATIVO | CJ14: 36757 | CK14: 55826 | CL14: 60438 | CM14: 50114
A15: 1 | B15: EM LINHA DISPONIVEL | D15: 197000 | E15: 223027 | F15: 230513 | G15: 231174 | H15: 255028 | I15: =316386+3241 -> 319627 | J15: 377712 | K15: 382411 | L15: 394107 | M15: 267954 | O15: 143875 | R15: 208084 | S15: 268431 | T15: 250616 | U15: 237088 | V15: 147777 | W15: 215818 | X15: 273510 | Y15: 299059 | Z15: 304980 | AA15: 231197 | AB15: 143086 | AC15: 172491 | AF15: 198695 | AG15: 234210 | AH15: 327560 | AI15: 332523 | AJ15: 356667 | AK15: 384165 | AL15: 317268 | AM15: 370708 | AN15: 354503 | AO15: 314605 | AP15: 90490 | AQ15: 58348 | AR15: =AQ15 -> 58348 | AT15: 158701 | AU15: 115369 | AV15: 142379 | AW15: 118765 | AX15: 113246 | AY15: 106776 | AZ15: 175234 | BA15: 151553 | BB15: 167082 | BC15: 150959 | BD15: 119787 | BE15: 65426 | BF15: =BE15 -> 65426 | BH15: 166918 | BI15: 167160 | BJ15: 204571 | BK15: 153197 | BL15: 196798 | BM15: 145596 | BN15: 166021 | BO15: 211305 | BP15: 201071 | BQ15: 177743 | BR15: 144020 | BS15: 154347 | BT15: =BS15 -> 154347 | BV15: 151471 | BW15: 155653 | BX15: 151611 | BY15: 177044 | BZ15: 170481 | CA15: 221665 | CB15: 218105 | CC15: 188153 | CD15: 147751 | CE15: 112996 | CF15: 135968 | CG15: 130000 | CH15: =CG15 -> 130000 | CI15: 114000 | CJ15: 109585 | CK15: 103815 | CL15: 117138 | CM15: =CL15+CM71-CM27 -> 137081.34 | CN15: =CM15+CN71-CN27 -> 172279.39 | CO15: =CN15+CO71-CO27 -> 245598.51 | CP15: =CO15+CP71-CP27 -> 235878.42 | CQ15: =CP15+CQ71-CQ27 -> 235983.11 | CR15: =CQ15+CR71-CR27 -> 177129.47 | CS15: =CR15+CS71-CS27 -> 163912.55 | CT15: =CS15+CT71-CT27 -> 175927.46 | CU15: =CT15+CU71-CU27 -> 192343.64 | CX15: =CU15+CX71-CX27 -> 185849.55 | CY15: =CX15+CY71-CY27 -> 149704.25 | CZ15: =CY15+CZ71-CZ27 -> 129417.74 | DA15: =CZ15+DA71-DA27 -> 145358.24 | DB15: =DA15+DB71-DB27 -> 177066.2 | DC15: =DB15+DC71-DC27 -> 234876.27 | DD15: =DC15+DD71-DD27 -> 209470.18 | DE15: =DD15+DE71-DE27 -> 185430.1 | DF15: =DE15+DF71-DF27 -> 99943.779 | ... DI15: =DH15+DI71-DI27 -> 85788.657 | DJ15: 0
A16: 2 | B16: EM LINHA NAO COMPRAR MP DISPONIVEL | D16: 73670 | E16: 59682 | F16: 54710 | G16: 56175 | H16: 58933 | I16: 42784 | J16: 35755 | K16: 33547 | L16: 22824 | M16: 26162 | O16: 44389 | R16: 39759 | S16: 38325 | T16: 26634 | U16: =14430+2754+7859 -> 25043 | V16: 23840 | W16: 20057 | X16: 80502 | Y16: 56483 | Z16: 44233 | AA16: 38155 | AB16: 27540 | AC16: 25060 | AF16: 21326 | AG16: 17804 | AH16: 27157 | AI16: 19677 | AJ16: 18817 | AK16: 25034 | AL16: 28090 | AM16: 25660 | AN16: 33752 | AO16: 24699 | AP16: 19340 | AQ16: 29842 | AR16: =AQ16 -> 29842 | AT16: 46493 | AU16: 37125 | AV16: 38574 | AW16: 43626 | AX16: 39641 | AY16: 55553 | AZ16: 48023 | BA16: 55043 | BB16: 50383 | BC16: 54355 | BD16: 82473 | BE16: 65398 | BF16: =BE16 -> 65398 | BH16: 68747 | BI16: 62843 | BJ16: 62154 | BK16: 49337 | BL16: 27730 | BM16: 42459 | BN16: 44049 | BO16: 29196 | BP16: 36882 | BQ16: 35965 | BR16: 31343 | BS16: 23087 | BT16: =BS16 -> 23087 | BV16: 15202 | BW16: 12471 | BX16: 11483 | BY16: 14071 | BZ16: 49617 | CA16: 36385 | CB16: 25473 | CC16: 16933 | CD16: 12684 | CE16: 21084 | CF16: 15172 | CG16: 11469 | CH16: =CG16 -> 11469 | CI16: =7500*5 -> 37500 | CJ16: 9465 | CK16: 13722 | CL16: 10771 | CM16: 8991 | CV16: 0 | DJ16: 0
A17: 3 | B17: EM LINHA PARADO (cob >3) DISPONIVEL | D17: 34116 | E17: 29277 | F17: 43008 | G17: 30524 | H17: 33235 | I17: 39842 | J17: 41021 | K17: 31224 | M17: 10286 | R17: 35516 | S17: 35962 | T17: 35962 | U17: 35962 | V17: 35000 | X17: 6123 | Y17: 6123 | Z17: 4187 | AA17: 2745 | AF17: 8366 | AG17: 11534 | AH17: 11507 | AI17: 9148 | AJ17: 8524 | AK17: 25290 | AL17: 91080 | AM17: 66830 | AN17: 36866 | AO17: 16173 | AP17: 178274 | AQ17: 210665 | AR17: =AQ17 -> 210665 | AT17: 121075 | AU17: 149376 | AV17: 104538 | AW17: 105262 | AX17: 121073 | AY17: 163931 | AZ17: 109964 | BA17: 148266 | BB17: 130697 | BC17: 113779 | BD17: 91119 | BE17: 103286 | BF17: =BE17 -> 103286 | BH17: 49631 | BI17: 52953 | BJ17: 28440 | BK17: 83601 | BL17: 25812 | BM17: 59545 | BN17: 83435 | BO17: 34041 | BP17: 22399 | BQ17: 24887 | BR17: 12183 | BS17: 12183 | BT17: =BS17 -> 12183 | BV17: 5216 | BX17: 65273 | BY17: 70182 | BZ17: 57659 | CA17: 71669 | CB17: 73078 | CC17: 85302 | CD17: 25343 | CE17: 19030 | CF17: 19422 | CG17: 25927 | CH17: =CG17 -> 25927 | CI17: 29000 | CJ17: 21580 | CK17: 18052 | CL17: 30722 | CM17: 55095 | CV17: 0 | DJ17: 0
A18: 4 | B18: EM LINHA PARADO (cob >6) DISPONIVEL | D18: 34116 | E18: 29277 | F18: 43008 | G18: 30524 | H18: 33235 | I18: 39842 | J18: 41021 | K18: 31224 | M18: 10286 | R18: 35516 | S18: 35962 | T18: 35962 | U18: 35962 | V18: 35000 | X18: 6123 | Y18: 6123 | Z18: 4187 | AA18: 2745 | AF18: 8366 | AG18: 11534 | AH18: 11507 | AI18: 9148 | AJ18: 8524 | AK18: 25290 | AL18: 91080 | AM18: 66830 | AN18: 36866 | AO18: 16173 | AP18: 178274 | AQ18: 210665 | AR18: =AQ18 -> 210665 | AT18: 121075 | AU18: 149376 | AV18: 104538 | AW18: 105262 | AX18: 121073 | AY18: 163931 | AZ18: 109964 | BA18: 148266 | BB18: 130697 | BC18: 113779 | BD18: 91119 | BE18: 103286 | BF18: =BE18 -> 103286 | BH18: 49631 | BI18: 52953 | BJ18: 28440 | BK18: 83601 | BL18: 25812 | BM18: 59545 | BN18: 83435 | BO18: 34041 | BP18: 22399 | BQ18: 24887 | BR18: 12183 | BS18: 12183 | BT18: =BS18 -> 12183 | CD18: 6361 | CE18: 7759 | CF18: 6573 | CG18: 9541 | CH18: =CG18 -> 9541 | CI18: =CI15+CI16-CI17 -> 122500 | CJ18: 9582 | CK18: 7266 | CL18: 11364 | CM18: 15500 | CV18: 0 | DJ18: 0
